---
layout: post
title: "rubyで繰り返しの中で例外処理"
date: 2015-10-31 09:41:22
categories: ruby
---
<pre><code>require 'open-uri'
urls = %w(url1, url2, url3)
urls.each do |url|
  res = open(url)
end
</code></pre>

<p>open(url)で例外が発生しないときは、その場でresを返し、<br>
例外が発生したら次のurlを試したいのですが、<br>
どう書いたらいいでしょうか？</p>
