---
layout: post
title: Promiseのエラー処理について
date: 2017-10-20 10:31:52
categories: angular4
---
<p>以下を参考にPromise処理を追加しました。<br>
<a href="https://angular.io/tutorial/toh-pt6" rel="nofollow noreferrer">https://angular.io/tutorial/toh-pt6</a></p>

<p>例えば、以下のような処理で<br>
this.http.getがエラーとなった場合、<br>
「.catch」で指定した「handleError」が呼ばれることは確認できました。<br>
たとえば特定のエラーの場合にgetHeroes()の呼びもとに返すことは可能なのでしょうか？</p>

<p>下記のような場合に★１処理をそのまま続行させたいです。</p>

```
this.httpService.getHeroes()
  .then(response =&gt; {
    ★１
  })


private heroesUrl = 'api/heroes';  // URL to web api

constructor(private http: Http) { }

getHeroes(): Promise&lt;Hero[]&gt; {
  return this.http.get(this.heroesUrl)
             .toPromise()
             .then(response =&gt; response.json().data as Hero[])
             .catch(this.handleError);
}

private handleError(error: any): Promise&lt;any&gt; {
  console.error('An error occurred', error); // for demo purposes only
  return Promise.reject(error.message || error);
}
```
