---
layout: post
title: Swiftのclass内で自身の型を持ったリストにアクセスしようとすると例外が発生する理由
date: 2017-10-16 07:19:39
categories: swift
---
<p>以下のコードが正しいかも含めての質問になります。<br>
XCode9.0でSwift4のコードになります。</p>

<p>下記コードで実行しようとしたところ<br>
error: Execution was interrupted, reason: EXC_BAD_ACCESS (code=2, address=0x7fff5c02cff8).という例外が発生しました。<br>
1.理由をご教示いただきたいです<br>
2.そもそも下のコードは誤りでしょうか？<br>
  クラス内に自身のインスタンスを持ったり、自身のインスタンスの宣言<br>
　自身のインスタンスを格納する配列定義等は可能でしょうか？</p>

```
class Test{
    var test:Double{
        get{
            return self.test+100
        }
        set(a){
            self.test=a
        }
    }

    var testList:Array&lt;Test&gt; = Array()

    init(a:Double){
        self.test = a
        addTest(a:a)
    }

    func addTest(a:Double){
        let t:Test = Test(a:a)
        testList.append(t)
    }
}

var test1:Test = Test(a:1)　　※←例外表示場所
print(test1.testList[0].test)
```
