---
layout: post
title: Pythonでexec文字列の中にプログラムを書くとNameErrorになる
date: 2018-01-01 00:35:11
categories: python3
---
<!-- {% raw %} -->
<p>あけましておめでとうございます。本年もよろしくお願いします。<br>
Python3で以下のようなコードを実行したところ、エラーが発生しました。<br>
実験の趣旨はexecにプログラムを文字列で渡すことです。</p>

<pre><code>#! /usr/bin/env python3
# hash_exec_test.py

def exec_test(s):
    exec(s)

exec_test ('''
book = {"Apple":[120,15], "Orange":[95,32], "Banana":[60,71]}
print("↓↓One-Values↓↓")
print(book["Apple"])
print()
keys = [x for x in list(book.keys())]
print("↓↓All-Keys↓↓")
print(keys)
print()
values = [book[x] for x in list(book.keys())]
print("↓↓All-Values↓↓")
print(values)
''')
</code></pre>

<p>実行結果は以下のとおりです。</p>

<pre><code>$ ./hash_exec_test.py
↓↓One-Values↓↓
[120, 15]

↓↓All-Keys↓↓
['Apple', 'Banana', 'Orange']

Traceback (most recent call last):
  File "./hash_exec_test.py", line 19, in &lt;module&gt;
    ''')
  File "./hash_exec_test.py", line 5, in exec_test
    exec(s)
  File "&lt;string&gt;", line 10, in &lt;module&gt;
  File "&lt;string&gt;", line 10, in &lt;listcomp&gt;
NameError: name 'book' is not defined
</code></pre>

<p>bookという名前が定義されていない、と言われています。<br>
しかし、上ではbook["Apple"]という検索が成功していますし、その後でキーを取り出すことはできているのに、最後に値を取り出そうとすると成功しない理由が分かりません。</p>

<p>ちなみに、関数exec_testを介さずに、execに文字列を渡してみます。</p>

<pre><code>#! /usr/bin/env python3
# hash_exec_test.py

exec ('''
book = {"Apple":[120,15], "Orange":[95,32], "Banana":[60,71]}
print("↓↓One-Values↓↓")
print(book["Apple"])
print()
keys = [x for x in list(book.keys())]
print("↓↓All-Keys↓↓")
print(keys)
print()
values = [book[x] for x in list(book.keys())]
print("↓↓All-Values↓↓")
print(values)
''')
</code></pre>

<p>これだとうまくいきます。</p>

<pre><code>$ ./hash_exec_test.py
↓↓One-Values↓↓
[120, 15]

↓↓All-Keys↓↓
['Banana', 'Orange', 'Apple']

↓↓All-Values↓↓
[[60, 71], [95, 32], [120, 15]]
</code></pre>

<p>なお、ディクショナリ型bookをグローバル変数にしてみます。</p>

<pre><code>#! /usr/bin/env python3
# hash_exec_test.py

def exec_test(s):
    exec(s)

book = {"Apple":[120,15], "Orange":[95,32], "Banana":[60,71]}

exec_test ('''
print("↓↓One-Values↓↓")
print(book["Apple"])
print()
keys = [x for x in list(book.keys())]
print("↓↓All-Keys↓↓")
print(keys)
print()
values = [book[x] for x in list(book.keys())]
print("↓↓All-Values↓↓")
print(values)
''')
</code></pre>

<p>これでも、うまくいきます。</p>

<pre><code>$ ./hash_exec_test.py
↓↓One-Values↓↓
[120, 15]

↓↓All-Keys↓↓
['Orange', 'Apple', 'Banana']

↓↓All-Values↓↓
[[95, 32], [120, 15], [60, 71]]
</code></pre>

<p>なぜ一番上のケースで、値のリストを得ようとするところだけNameErrorになるのでしょうか。<br>
ご教示願います。<br>
ちなみに環境は以下のとおりです。</p>

<pre><code>$ uname -a
Linux DESKTOP-AHPUUO5 4.4.0-43-Microsoft #1-Microsoft Wed Dec 31 14:42:53 PST 2014 x86_64 x86_64 x86_64 GNU/Linux
$ python3 -V
Python 3.5.2
</code></pre>

<p>（2017-01-02 11:51 追記）<br>
ローカル変数の定義状況を示すためにprint(locals())を加えてみました。</p>

<pre><code>#! /usr/bin/env python3
# hash_exec_test.py
def exec_test(s):
    exec(s)

exec_test ('''
book = {"Apple":[120,15], "Orange":[95,32], "Banana":[60,71]}
print("locals")
print(locals())
print()
print("One-Values:")
print(book["Apple"])
print()
keys = [x for x in list(book.keys())]
print("All-Keys")
print(keys)
print()
print("locals in the list comprehension")
values = [locals() for x in list(book.keys())]
print(values)
print("All-Values")
values = [book[x] for x in list(book.keys())]
print("All-Values")
print(values)
''')
</code></pre>

<p>実行結果は以下のとおりです。</p>

<pre><code>$ ./hash_exec_test.py
locals
{'s': '\nbook = {"Apple":[120,15], "Orange":[95,32], "Banana":[60,71]}\nprint("locals")\nprint(locals())\nprint()\nprint("One-Values:")\nprint(book["Apple"])\nprint()\nkeys = [x for x in list(book.keys())]\nprint("All-Keys")\nprint(keys)\nprint()\nprint("locals in the list comprehension")\nvalues = [locals() for x in list(book.keys())]\nprint(values)\nprint("All-Values")\nvalues = [book[x] for x in list(book.keys())]\nprint("All-Values")\nprint(values)\n', 'book': {'Banana': [60, 71], 'Orange': [95, 32], 'Apple': [120, 15]}}

One-Values:
[120, 15]

All-Keys
['Banana', 'Orange', 'Apple']

locals in the list comprehension
[{'x': 'Apple', '.0': &lt;list_iterator object at 0x7f871a502470&gt;}, {'x': 'Apple', '.0': &lt;list_iterator object at 0x7f871a502470&gt;}, {'x': 'Apple', '.0': &lt;list_iterator object at 0x7f871a502470&gt;}]
All-Values
Traceback (most recent call last):
  File "./hash_exec_test.py", line 25, in &lt;module&gt;
    ''')
  File "./hash_exec_test.py", line 4, in exec_test
    exec(s)
  File "&lt;string&gt;", line 17, in &lt;module&gt;
  File "&lt;string&gt;", line 17, in &lt;listcomp&gt;
NameError: name 'book' is not defined
</code></pre>

<p>リスト内包表記の中ではローカル変数bookが定義されていません。<br>
これが原因なのでしょう。<br>
ではなぜ</p>

<pre><code>keys = [x for x in list(book.keys())]
</code></pre>

<p>は正しく動いたかというと、book.keys()は&lt;list_iterator object at 0x7f871a502470&gt;を介して（？）bookにアクセスできていたということでしょうか。</p>
<!-- {% endraw %} -->
