---
layout: post
title: sqlalchemy + pymysql にて、 stream_results=True にしたら Lost connection to server during query が出た時の対処方法
date: 2019-08-31 04:33:59
categories: mysql sqlalchemy pymysql
---
<p>sqlalchemy+pymysql で MySQL サーバーから大量のレコードを select しようとしました。</p>

<p>その際、 stream_results=True の設定を行うと、 select から 2,3 分ほど経った段階で、</p>

<blockquote>
  <p>Lost connection to server during query</p>
</blockquote>

<p>のエラーが発生し、 select が途中で中断してしまいます。なお、 stream_results=True を付与しなければ、この問題は発生しませんでした。</p>

<p><a href="https://dev.mysql.com/doc/refman/8.0/en/error-lost-connection.html" rel="nofollow noreferrer">https://dev.mysql.com/doc/refman/8.0/en/error-lost-connection.html</a></p>

<p>上記ページをみてみても、</p>

<ol>
<li><code>net_read_timeout</code> => 3600 にしたけど、 2,3分で例外発生</li>
<li><code>connection_timeout</code> => 最初の何件かは select できていることを確認したので、 establish connection まわりの例外ではなさそう</li>
<li><code>max_allowed_packet</code> => MySQL Workbench で、個別に例外が発生したタイミングで select していたレコードたちを個別で select してみると、問題なく select できる</li>
</ol>

<p>であり、解決に至っていません。</p>

<h1>質問</h1>

<ul>
<li>何が原因で、この問題は発生していますか？</li>
</ul>
