---
layout: post
title: oandapyからデモ口座の口座情報を参照するとエラーコード52が出る
date: 2019-04-15 07:35:26
categories: python jupyter-notebook
---
<p>環境はWindoes 10, Jupyter notebook, python 3.6.8です。<br>
oandaのデモ口座の情報を以下のコードで参照しようとしました。</p>

<pre><code>!pip install git+https://github.com/oanda/oandapy.git
import oandapy

account_id = '*******'
api_key = '***********'
oanda = oandapy.API(environment="practice", access_token=api_key)

account_detail = oanda.get_account('vd787106')
account_detailコードをここに入力
</code></pre>

<p>これを実行したところ、以下のエラーが出ました。</p>

<pre><code>OandaError                                Traceback (most recent call last)
&lt;ipython-input-27-f251f8ccb763&gt; in &lt;module&gt;
----&gt; 1 res_acct_detail = oanda.get_account('vd787106')
      2 res_acct_detail

C:\ProgramData\Anaconda3\lib\site-packages\oandapy\oandapy.py in get_account(self, account_id, **params)
     59         """
     60         endpoint = 'v1/accounts/%s' % (account_id)
---&gt; 61         return self.request(endpoint, params=params)
     62 
     63     """Orders"""

C:\ProgramData\Anaconda3\lib\site-packages\oandapy\oandapy.py in request(self, endpoint, method, params)
    282         # error message
    283         if response.status_code &gt;= 400:
--&gt; 284             raise OandaError(content)
    285 
    286         return content

OandaError: OANDA API returned error code 52 (Invalid or malformed resource identifier: accountId) 
</code></pre>

<p>解決法をご存知の方がいましたら、ご教授頂きたいです。よろしくお願いします。</p>
